2017-05-13 03:01:03,216 Traceback (most recent call last):
  File "D:\ldap\src\server\env\lib\site-packages\flask\app.py", line 1639, in full_dispatch_request
    rv = self.dispatch_request()
  File "D:\ldap\src\server\env\lib\site-packages\flask\app.py", line 1617, in dispatch_request
    self.raise_routing_exception(req)
  File "D:\ldap\src\server\env\lib\site-packages\flask\app.py", line 1600, in raise_routing_exception
    raise request.routing_exception
NotFound: 404: Not Found

2017-05-13 03:01:03,240 Traceback (most recent call last):
  File "D:\ldap\src\server\env\lib\site-packages\flask\app.py", line 1988, in wsgi_app
    response = self.full_dispatch_request()
  File "D:\ldap\src\server\env\lib\site-packages\flask\app.py", line 1641, in full_dispatch_request
    rv = self.handle_user_exception(e)
  File "D:\ldap\src\server\env\lib\site-packages\flask_restful\__init__.py", line 271, in error_router
    return original_handler(e)
  File "D:\ldap\src\server\env\lib\site-packages\flask_cors\extension.py", line 161, in wrapped_function
    return cors_after_request(app.make_response(f(*args, **kwargs)))
  File "D:\ldap\src\server\env\lib\site-packages\flask\app.py", line 1746, in make_response
    rv = self.response_class.force_type(rv, request.environ)
  File "D:\ldap\src\server\env\lib\site-packages\werkzeug\wrappers.py", line 847, in force_type
    response = BaseResponse(*_run_wsgi_app(response, environ))
  File "D:\ldap\src\server\env\lib\site-packages\werkzeug\wrappers.py", line 57, in _run_wsgi_app
    return _run_wsgi_app(*args)
  File "D:\ldap\src\server\env\lib\site-packages\werkzeug\test.py", line 871, in run_wsgi_app
    app_rv = app(environ, start_response)
TypeError: 'int' object is not callable

2017-05-13 03:02:54,552 Traceback (most recent call last):
  File "D:\ldap\src\server\env\lib\site-packages\flask\app.py", line 1639, in full_dispatch_request
    rv = self.dispatch_request()
  File "D:\ldap\src\server\env\lib\site-packages\flask\app.py", line 1617, in dispatch_request
    self.raise_routing_exception(req)
  File "D:\ldap\src\server\env\lib\site-packages\flask\app.py", line 1600, in raise_routing_exception
    raise request.routing_exception
NotFound: 404: Not Found

2017-05-13 03:02:54,556 Traceback (most recent call last):
  File "D:\ldap\src\server\env\lib\site-packages\flask\app.py", line 1988, in wsgi_app
    response = self.full_dispatch_request()
  File "D:\ldap\src\server\env\lib\site-packages\flask\app.py", line 1641, in full_dispatch_request
    rv = self.handle_user_exception(e)
  File "D:\ldap\src\server\env\lib\site-packages\flask_restful\__init__.py", line 271, in error_router
    return original_handler(e)
  File "D:\ldap\src\server\env\lib\site-packages\flask_cors\extension.py", line 161, in wrapped_function
    return cors_after_request(app.make_response(f(*args, **kwargs)))
  File "D:\ldap\src\server\env\lib\site-packages\flask\app.py", line 1746, in make_response
    rv = self.response_class.force_type(rv, request.environ)
  File "D:\ldap\src\server\env\lib\site-packages\werkzeug\wrappers.py", line 847, in force_type
    response = BaseResponse(*_run_wsgi_app(response, environ))
  File "D:\ldap\src\server\env\lib\site-packages\werkzeug\wrappers.py", line 57, in _run_wsgi_app
    return _run_wsgi_app(*args)
  File "D:\ldap\src\server\env\lib\site-packages\werkzeug\test.py", line 871, in run_wsgi_app
    app_rv = app(environ, start_response)
TypeError: 'int' object is not callable

2017-05-13 03:09:41,914 Traceback (most recent call last):
  File "D:\ldap\src\server\env\lib\site-packages\flask\app.py", line 1639, in full_dispatch_request
    rv = self.dispatch_request()
  File "D:\ldap\src\server\env\lib\site-packages\flask\app.py", line 1617, in dispatch_request
    self.raise_routing_exception(req)
  File "D:\ldap\src\server\env\lib\site-packages\flask\app.py", line 1600, in raise_routing_exception
    raise request.routing_exception
NotFound: 404: Not Found

2017-05-13 03:09:41,921 Traceback (most recent call last):
  File "D:\ldap\src\server\env\lib\site-packages\flask\app.py", line 1988, in wsgi_app
    response = self.full_dispatch_request()
  File "D:\ldap\src\server\env\lib\site-packages\flask\app.py", line 1641, in full_dispatch_request
    rv = self.handle_user_exception(e)
  File "D:\ldap\src\server\env\lib\site-packages\flask_restful\__init__.py", line 271, in error_router
    return original_handler(e)
  File "D:\ldap\src\server\env\lib\site-packages\flask_cors\extension.py", line 161, in wrapped_function
    return cors_after_request(app.make_response(f(*args, **kwargs)))
  File "D:\ldap\src\server\env\lib\site-packages\flask\app.py", line 1746, in make_response
    rv = self.response_class.force_type(rv, request.environ)
  File "D:\ldap\src\server\env\lib\site-packages\werkzeug\wrappers.py", line 847, in force_type
    response = BaseResponse(*_run_wsgi_app(response, environ))
  File "D:\ldap\src\server\env\lib\site-packages\werkzeug\wrappers.py", line 57, in _run_wsgi_app
    return _run_wsgi_app(*args)
  File "D:\ldap\src\server\env\lib\site-packages\werkzeug\test.py", line 871, in run_wsgi_app
    app_rv = app(environ, start_response)
TypeError: 'int' object is not callable

2017-05-13 03:12:12,331 Traceback (most recent call last):
  File "D:\ldap\src\server\env\lib\site-packages\flask\app.py", line 1639, in full_dispatch_request
    rv = self.dispatch_request()
  File "D:\ldap\src\server\env\lib\site-packages\flask\app.py", line 1617, in dispatch_request
    self.raise_routing_exception(req)
  File "D:\ldap\src\server\env\lib\site-packages\flask\app.py", line 1600, in raise_routing_exception
    raise request.routing_exception
NotFound: 404: Not Found

2017-05-13 03:12:12,335 Traceback (most recent call last):
  File "D:\ldap\src\server\env\lib\site-packages\flask\app.py", line 1988, in wsgi_app
    response = self.full_dispatch_request()
  File "D:\ldap\src\server\env\lib\site-packages\flask\app.py", line 1641, in full_dispatch_request
    rv = self.handle_user_exception(e)
  File "D:\ldap\src\server\env\lib\site-packages\flask_restful\__init__.py", line 271, in error_router
    return original_handler(e)
  File "D:\ldap\src\server\env\lib\site-packages\flask_cors\extension.py", line 161, in wrapped_function
    return cors_after_request(app.make_response(f(*args, **kwargs)))
  File "D:\ldap\src\server\env\lib\site-packages\flask\app.py", line 1746, in make_response
    rv = self.response_class.force_type(rv, request.environ)
  File "D:\ldap\src\server\env\lib\site-packages\werkzeug\wrappers.py", line 847, in force_type
    response = BaseResponse(*_run_wsgi_app(response, environ))
  File "D:\ldap\src\server\env\lib\site-packages\werkzeug\wrappers.py", line 57, in _run_wsgi_app
    return _run_wsgi_app(*args)
  File "D:\ldap\src\server\env\lib\site-packages\werkzeug\test.py", line 871, in run_wsgi_app
    app_rv = app(environ, start_response)
TypeError: 'int' object is not callable

2019-11-24 17:26:12,970 Traceback (most recent call last):
  File "C:\Users\kor_file\Anaconda3\envs\tensorflow_p36\lib\site-packages\flask\app.py", line 1949, in full_dispatch_request
    rv = self.dispatch_request()
  File "C:\Users\kor_file\Anaconda3\envs\tensorflow_p36\lib\site-packages\flask\app.py", line 1925, in dispatch_request
    self.raise_routing_exception(req)
  File "C:\Users\kor_file\Anaconda3\envs\tensorflow_p36\lib\site-packages\flask\app.py", line 1907, in raise_routing_exception
    raise request.routing_exception
  File "C:\Users\kor_file\Anaconda3\envs\tensorflow_p36\lib\site-packages\flask\ctx.py", line 350, in match_request
    result = self.url_adapter.match(return_rule=True)
  File "C:\Users\kor_file\AppData\Roaming\Python\Python36\site-packages\werkzeug\routing.py", line 1799, in match
    raise NotFound()
werkzeug.exceptions.NotFound: 404 Not Found: The requested URL was not found on the server. If you entered the URL manually please check your spelling and try again.

2019-11-24 17:26:12,975 Traceback (most recent call last):
  File "C:\Users\kor_file\Anaconda3\envs\tensorflow_p36\lib\site-packages\flask\app.py", line 1949, in full_dispatch_request
    rv = self.dispatch_request()
  File "C:\Users\kor_file\Anaconda3\envs\tensorflow_p36\lib\site-packages\flask\app.py", line 1925, in dispatch_request
    self.raise_routing_exception(req)
  File "C:\Users\kor_file\Anaconda3\envs\tensorflow_p36\lib\site-packages\flask\app.py", line 1907, in raise_routing_exception
    raise request.routing_exception
  File "C:\Users\kor_file\Anaconda3\envs\tensorflow_p36\lib\site-packages\flask\ctx.py", line 350, in match_request
    result = self.url_adapter.match(return_rule=True)
  File "C:\Users\kor_file\AppData\Roaming\Python\Python36\site-packages\werkzeug\routing.py", line 1799, in match
    raise NotFound()
werkzeug.exceptions.NotFound: 404 Not Found: The requested URL was not found on the server. If you entered the URL manually please check your spelling and try again.

During handling of the above exception, another exception occurred:

Traceback (most recent call last):
  File "C:\Users\kor_file\Anaconda3\envs\tensorflow_p36\lib\site-packages\flask\app.py", line 2446, in wsgi_app
    response = self.full_dispatch_request()
  File "C:\Users\kor_file\Anaconda3\envs\tensorflow_p36\lib\site-packages\flask\app.py", line 1951, in full_dispatch_request
    rv = self.handle_user_exception(e)
  File "C:\Users\kor_file\Anaconda3\envs\tensorflow_p36\lib\site-packages\flask_restful\__init__.py", line 269, in error_router
    return original_handler(e)
  File "C:\Users\kor_file\Anaconda3\envs\tensorflow_p36\lib\site-packages\flask_cors\extension.py", line 161, in wrapped_function
    return cors_after_request(app.make_response(f(*args, **kwargs)))
  File "C:\Users\kor_file\Anaconda3\envs\tensorflow_p36\lib\site-packages\flask\app.py", line 2130, in make_response
    " {rv.__class__.__name__}.".format(rv=rv)
TypeError: The view function did not return a valid response. The return type must be a string, dict, tuple, Response instance, or WSGI callable, but it was a int.

2019-12-02 15:43:00,261 Traceback (most recent call last):
  File "C:\Users\kor_file\Anaconda3\envs\tensorflow_p36\lib\site-packages\flask\app.py", line 1949, in full_dispatch_request
    rv = self.dispatch_request()
  File "C:\Users\kor_file\Anaconda3\envs\tensorflow_p36\lib\site-packages\flask\app.py", line 1925, in dispatch_request
    self.raise_routing_exception(req)
  File "C:\Users\kor_file\Anaconda3\envs\tensorflow_p36\lib\site-packages\flask\app.py", line 1907, in raise_routing_exception
    raise request.routing_exception
  File "C:\Users\kor_file\Anaconda3\envs\tensorflow_p36\lib\site-packages\flask\ctx.py", line 350, in match_request
    result = self.url_adapter.match(return_rule=True)
  File "C:\Users\kor_file\AppData\Roaming\Python\Python36\site-packages\werkzeug\routing.py", line 1799, in match
    raise NotFound()
werkzeug.exceptions.NotFound: 404 Not Found: The requested URL was not found on the server. If you entered the URL manually please check your spelling and try again.

2019-12-02 15:43:00,266 Traceback (most recent call last):
  File "C:\Users\kor_file\Anaconda3\envs\tensorflow_p36\lib\site-packages\flask\app.py", line 1949, in full_dispatch_request
    rv = self.dispatch_request()
  File "C:\Users\kor_file\Anaconda3\envs\tensorflow_p36\lib\site-packages\flask\app.py", line 1925, in dispatch_request
    self.raise_routing_exception(req)
  File "C:\Users\kor_file\Anaconda3\envs\tensorflow_p36\lib\site-packages\flask\app.py", line 1907, in raise_routing_exception
    raise request.routing_exception
  File "C:\Users\kor_file\Anaconda3\envs\tensorflow_p36\lib\site-packages\flask\ctx.py", line 350, in match_request
    result = self.url_adapter.match(return_rule=True)
  File "C:\Users\kor_file\AppData\Roaming\Python\Python36\site-packages\werkzeug\routing.py", line 1799, in match
    raise NotFound()
werkzeug.exceptions.NotFound: 404 Not Found: The requested URL was not found on the server. If you entered the URL manually please check your spelling and try again.

During handling of the above exception, another exception occurred:

Traceback (most recent call last):
  File "C:\Users\kor_file\Anaconda3\envs\tensorflow_p36\lib\site-packages\flask\app.py", line 2446, in wsgi_app
    response = self.full_dispatch_request()
  File "C:\Users\kor_file\Anaconda3\envs\tensorflow_p36\lib\site-packages\flask\app.py", line 1951, in full_dispatch_request
    rv = self.handle_user_exception(e)
  File "C:\Users\kor_file\Anaconda3\envs\tensorflow_p36\lib\site-packages\flask_restful\__init__.py", line 269, in error_router
    return original_handler(e)
  File "C:\Users\kor_file\Anaconda3\envs\tensorflow_p36\lib\site-packages\flask_cors\extension.py", line 161, in wrapped_function
    return cors_after_request(app.make_response(f(*args, **kwargs)))
  File "C:\Users\kor_file\Anaconda3\envs\tensorflow_p36\lib\site-packages\flask\app.py", line 2130, in make_response
    " {rv.__class__.__name__}.".format(rv=rv)
TypeError: The view function did not return a valid response. The return type must be a string, dict, tuple, Response instance, or WSGI callable, but it was a int.

2019-12-03 20:44:26,103 Traceback (most recent call last):
  File "C:\Users\kor_file\Anaconda3\envs\tensorflow_p36\lib\site-packages\flask\app.py", line 1949, in full_dispatch_request
    rv = self.dispatch_request()
  File "C:\Users\kor_file\Anaconda3\envs\tensorflow_p36\lib\site-packages\flask\app.py", line 1925, in dispatch_request
    self.raise_routing_exception(req)
  File "C:\Users\kor_file\Anaconda3\envs\tensorflow_p36\lib\site-packages\flask\app.py", line 1907, in raise_routing_exception
    raise request.routing_exception
  File "C:\Users\kor_file\Anaconda3\envs\tensorflow_p36\lib\site-packages\flask\ctx.py", line 350, in match_request
    result = self.url_adapter.match(return_rule=True)
  File "C:\Users\kor_file\AppData\Roaming\Python\Python36\site-packages\werkzeug\routing.py", line 1799, in match
    raise NotFound()
werkzeug.exceptions.NotFound: 404 Not Found: The requested URL was not found on the server. If you entered the URL manually please check your spelling and try again.

2019-12-03 20:44:26,111 Traceback (most recent call last):
  File "C:\Users\kor_file\Anaconda3\envs\tensorflow_p36\lib\site-packages\flask\app.py", line 1949, in full_dispatch_request
    rv = self.dispatch_request()
  File "C:\Users\kor_file\Anaconda3\envs\tensorflow_p36\lib\site-packages\flask\app.py", line 1925, in dispatch_request
    self.raise_routing_exception(req)
  File "C:\Users\kor_file\Anaconda3\envs\tensorflow_p36\lib\site-packages\flask\app.py", line 1907, in raise_routing_exception
    raise request.routing_exception
  File "C:\Users\kor_file\Anaconda3\envs\tensorflow_p36\lib\site-packages\flask\ctx.py", line 350, in match_request
    result = self.url_adapter.match(return_rule=True)
  File "C:\Users\kor_file\AppData\Roaming\Python\Python36\site-packages\werkzeug\routing.py", line 1799, in match
    raise NotFound()
werkzeug.exceptions.NotFound: 404 Not Found: The requested URL was not found on the server. If you entered the URL manually please check your spelling and try again.

During handling of the above exception, another exception occurred:

Traceback (most recent call last):
  File "C:\Users\kor_file\Anaconda3\envs\tensorflow_p36\lib\site-packages\flask\app.py", line 2446, in wsgi_app
    response = self.full_dispatch_request()
  File "C:\Users\kor_file\Anaconda3\envs\tensorflow_p36\lib\site-packages\flask\app.py", line 1951, in full_dispatch_request
    rv = self.handle_user_exception(e)
  File "C:\Users\kor_file\Anaconda3\envs\tensorflow_p36\lib\site-packages\flask_restful\__init__.py", line 269, in error_router
    return original_handler(e)
  File "C:\Users\kor_file\Anaconda3\envs\tensorflow_p36\lib\site-packages\flask_cors\extension.py", line 161, in wrapped_function
    return cors_after_request(app.make_response(f(*args, **kwargs)))
  File "C:\Users\kor_file\Anaconda3\envs\tensorflow_p36\lib\site-packages\flask\app.py", line 2130, in make_response
    " {rv.__class__.__name__}.".format(rv=rv)
TypeError: The view function did not return a valid response. The return type must be a string, dict, tuple, Response instance, or WSGI callable, but it was a int.

2019-12-03 20:47:51,438 Traceback (most recent call last):
  File "C:\Users\kor_file\Anaconda3\envs\tensorflow_p36\lib\site-packages\flask\app.py", line 1949, in full_dispatch_request
    rv = self.dispatch_request()
  File "C:\Users\kor_file\Anaconda3\envs\tensorflow_p36\lib\site-packages\flask\app.py", line 1925, in dispatch_request
    self.raise_routing_exception(req)
  File "C:\Users\kor_file\Anaconda3\envs\tensorflow_p36\lib\site-packages\flask\app.py", line 1907, in raise_routing_exception
    raise request.routing_exception
  File "C:\Users\kor_file\Anaconda3\envs\tensorflow_p36\lib\site-packages\flask\ctx.py", line 350, in match_request
    result = self.url_adapter.match(return_rule=True)
  File "C:\Users\kor_file\AppData\Roaming\Python\Python36\site-packages\werkzeug\routing.py", line 1799, in match
    raise NotFound()
werkzeug.exceptions.NotFound: 404 Not Found: The requested URL was not found on the server. If you entered the URL manually please check your spelling and try again.

2019-12-03 20:47:51,442 Traceback (most recent call last):
  File "C:\Users\kor_file\Anaconda3\envs\tensorflow_p36\lib\site-packages\flask\app.py", line 1949, in full_dispatch_request
    rv = self.dispatch_request()
  File "C:\Users\kor_file\Anaconda3\envs\tensorflow_p36\lib\site-packages\flask\app.py", line 1925, in dispatch_request
    self.raise_routing_exception(req)
  File "C:\Users\kor_file\Anaconda3\envs\tensorflow_p36\lib\site-packages\flask\app.py", line 1907, in raise_routing_exception
    raise request.routing_exception
  File "C:\Users\kor_file\Anaconda3\envs\tensorflow_p36\lib\site-packages\flask\ctx.py", line 350, in match_request
    result = self.url_adapter.match(return_rule=True)
  File "C:\Users\kor_file\AppData\Roaming\Python\Python36\site-packages\werkzeug\routing.py", line 1799, in match
    raise NotFound()
werkzeug.exceptions.NotFound: 404 Not Found: The requested URL was not found on the server. If you entered the URL manually please check your spelling and try again.

During handling of the above exception, another exception occurred:

Traceback (most recent call last):
  File "C:\Users\kor_file\Anaconda3\envs\tensorflow_p36\lib\site-packages\flask\app.py", line 2446, in wsgi_app
    response = self.full_dispatch_request()
  File "C:\Users\kor_file\Anaconda3\envs\tensorflow_p36\lib\site-packages\flask\app.py", line 1951, in full_dispatch_request
    rv = self.handle_user_exception(e)
  File "C:\Users\kor_file\Anaconda3\envs\tensorflow_p36\lib\site-packages\flask_restful\__init__.py", line 269, in error_router
    return original_handler(e)
  File "C:\Users\kor_file\Anaconda3\envs\tensorflow_p36\lib\site-packages\flask_cors\extension.py", line 161, in wrapped_function
    return cors_after_request(app.make_response(f(*args, **kwargs)))
  File "C:\Users\kor_file\Anaconda3\envs\tensorflow_p36\lib\site-packages\flask\app.py", line 2130, in make_response
    " {rv.__class__.__name__}.".format(rv=rv)
TypeError: The view function did not return a valid response. The return type must be a string, dict, tuple, Response instance, or WSGI callable, but it was a int.

2019-12-07 12:16:30,475 Traceback (most recent call last):
  File "C:\Users\kor_file\Anaconda3\envs\tensorflow_p36\lib\site-packages\flask\app.py", line 1949, in full_dispatch_request
    rv = self.dispatch_request()
  File "C:\Users\kor_file\Anaconda3\envs\tensorflow_p36\lib\site-packages\flask\app.py", line 1925, in dispatch_request
    self.raise_routing_exception(req)
  File "C:\Users\kor_file\Anaconda3\envs\tensorflow_p36\lib\site-packages\flask\app.py", line 1907, in raise_routing_exception
    raise request.routing_exception
  File "C:\Users\kor_file\Anaconda3\envs\tensorflow_p36\lib\site-packages\flask\ctx.py", line 350, in match_request
    result = self.url_adapter.match(return_rule=True)
  File "C:\Users\kor_file\AppData\Roaming\Python\Python36\site-packages\werkzeug\routing.py", line 1799, in match
    raise NotFound()
werkzeug.exceptions.NotFound: 404 Not Found: The requested URL was not found on the server. If you entered the URL manually please check your spelling and try again.

2019-12-07 12:16:30,481 Traceback (most recent call last):
  File "C:\Users\kor_file\Anaconda3\envs\tensorflow_p36\lib\site-packages\flask\app.py", line 1949, in full_dispatch_request
    rv = self.dispatch_request()
  File "C:\Users\kor_file\Anaconda3\envs\tensorflow_p36\lib\site-packages\flask\app.py", line 1925, in dispatch_request
    self.raise_routing_exception(req)
  File "C:\Users\kor_file\Anaconda3\envs\tensorflow_p36\lib\site-packages\flask\app.py", line 1907, in raise_routing_exception
    raise request.routing_exception
  File "C:\Users\kor_file\Anaconda3\envs\tensorflow_p36\lib\site-packages\flask\ctx.py", line 350, in match_request
    result = self.url_adapter.match(return_rule=True)
  File "C:\Users\kor_file\AppData\Roaming\Python\Python36\site-packages\werkzeug\routing.py", line 1799, in match
    raise NotFound()
werkzeug.exceptions.NotFound: 404 Not Found: The requested URL was not found on the server. If you entered the URL manually please check your spelling and try again.

During handling of the above exception, another exception occurred:

Traceback (most recent call last):
  File "C:\Users\kor_file\Anaconda3\envs\tensorflow_p36\lib\site-packages\flask\app.py", line 2446, in wsgi_app
    response = self.full_dispatch_request()
  File "C:\Users\kor_file\Anaconda3\envs\tensorflow_p36\lib\site-packages\flask\app.py", line 1951, in full_dispatch_request
    rv = self.handle_user_exception(e)
  File "C:\Users\kor_file\Anaconda3\envs\tensorflow_p36\lib\site-packages\flask_restful\__init__.py", line 269, in error_router
    return original_handler(e)
  File "C:\Users\kor_file\Anaconda3\envs\tensorflow_p36\lib\site-packages\flask_cors\extension.py", line 161, in wrapped_function
    return cors_after_request(app.make_response(f(*args, **kwargs)))
  File "C:\Users\kor_file\Anaconda3\envs\tensorflow_p36\lib\site-packages\flask\app.py", line 2130, in make_response
    " {rv.__class__.__name__}.".format(rv=rv)
TypeError: The view function did not return a valid response. The return type must be a string, dict, tuple, Response instance, or WSGI callable, but it was a int.

2019-12-13 13:43:20,035 Traceback (most recent call last):
  File "C:\Users\kor_file\Anaconda3\envs\tensorflow_p36\lib\site-packages\flask\app.py", line 1949, in full_dispatch_request
    rv = self.dispatch_request()
  File "C:\Users\kor_file\Anaconda3\envs\tensorflow_p36\lib\site-packages\flask\app.py", line 1925, in dispatch_request
    self.raise_routing_exception(req)
  File "C:\Users\kor_file\Anaconda3\envs\tensorflow_p36\lib\site-packages\flask\app.py", line 1907, in raise_routing_exception
    raise request.routing_exception
  File "C:\Users\kor_file\Anaconda3\envs\tensorflow_p36\lib\site-packages\flask\ctx.py", line 350, in match_request
    result = self.url_adapter.match(return_rule=True)
  File "C:\Users\kor_file\AppData\Roaming\Python\Python36\site-packages\werkzeug\routing.py", line 1799, in match
    raise NotFound()
werkzeug.exceptions.NotFound: 404 Not Found: The requested URL was not found on the server. If you entered the URL manually please check your spelling and try again.

2019-12-13 13:43:20,050 Traceback (most recent call last):
  File "C:\Users\kor_file\Anaconda3\envs\tensorflow_p36\lib\site-packages\flask\app.py", line 1949, in full_dispatch_request
    rv = self.dispatch_request()
  File "C:\Users\kor_file\Anaconda3\envs\tensorflow_p36\lib\site-packages\flask\app.py", line 1925, in dispatch_request
    self.raise_routing_exception(req)
  File "C:\Users\kor_file\Anaconda3\envs\tensorflow_p36\lib\site-packages\flask\app.py", line 1907, in raise_routing_exception
    raise request.routing_exception
  File "C:\Users\kor_file\Anaconda3\envs\tensorflow_p36\lib\site-packages\flask\ctx.py", line 350, in match_request
    result = self.url_adapter.match(return_rule=True)
  File "C:\Users\kor_file\AppData\Roaming\Python\Python36\site-packages\werkzeug\routing.py", line 1799, in match
    raise NotFound()
werkzeug.exceptions.NotFound: 404 Not Found: The requested URL was not found on the server. If you entered the URL manually please check your spelling and try again.

During handling of the above exception, another exception occurred:

Traceback (most recent call last):
  File "C:\Users\kor_file\Anaconda3\envs\tensorflow_p36\lib\site-packages\flask\app.py", line 2446, in wsgi_app
    response = self.full_dispatch_request()
  File "C:\Users\kor_file\Anaconda3\envs\tensorflow_p36\lib\site-packages\flask\app.py", line 1951, in full_dispatch_request
    rv = self.handle_user_exception(e)
  File "C:\Users\kor_file\Anaconda3\envs\tensorflow_p36\lib\site-packages\flask_restful\__init__.py", line 269, in error_router
    return original_handler(e)
  File "C:\Users\kor_file\Anaconda3\envs\tensorflow_p36\lib\site-packages\flask_cors\extension.py", line 161, in wrapped_function
    return cors_after_request(app.make_response(f(*args, **kwargs)))
  File "C:\Users\kor_file\Anaconda3\envs\tensorflow_p36\lib\site-packages\flask\app.py", line 2130, in make_response
    " {rv.__class__.__name__}.".format(rv=rv)
TypeError: The view function did not return a valid response. The return type must be a string, dict, tuple, Response instance, or WSGI callable, but it was a int.

2020-02-21 09:52:40,766 Traceback (most recent call last):
  File "C:\Users\kor_file\Anaconda3\envs\tensorflow_p36\lib\site-packages\flask\app.py", line 1949, in full_dispatch_request
    rv = self.dispatch_request()
  File "C:\Users\kor_file\Anaconda3\envs\tensorflow_p36\lib\site-packages\flask\app.py", line 1925, in dispatch_request
    self.raise_routing_exception(req)
  File "C:\Users\kor_file\Anaconda3\envs\tensorflow_p36\lib\site-packages\flask\app.py", line 1907, in raise_routing_exception
    raise request.routing_exception
  File "C:\Users\kor_file\Anaconda3\envs\tensorflow_p36\lib\site-packages\flask\ctx.py", line 350, in match_request
    result = self.url_adapter.match(return_rule=True)
  File "C:\Users\kor_file\AppData\Roaming\Python\Python36\site-packages\werkzeug\routing.py", line 1799, in match
    raise NotFound()
werkzeug.exceptions.NotFound: 404 Not Found: The requested URL was not found on the server. If you entered the URL manually please check your spelling and try again.

2020-02-21 09:52:40,771 Traceback (most recent call last):
  File "C:\Users\kor_file\Anaconda3\envs\tensorflow_p36\lib\site-packages\flask\app.py", line 1949, in full_dispatch_request
    rv = self.dispatch_request()
  File "C:\Users\kor_file\Anaconda3\envs\tensorflow_p36\lib\site-packages\flask\app.py", line 1925, in dispatch_request
    self.raise_routing_exception(req)
  File "C:\Users\kor_file\Anaconda3\envs\tensorflow_p36\lib\site-packages\flask\app.py", line 1907, in raise_routing_exception
    raise request.routing_exception
  File "C:\Users\kor_file\Anaconda3\envs\tensorflow_p36\lib\site-packages\flask\ctx.py", line 350, in match_request
    result = self.url_adapter.match(return_rule=True)
  File "C:\Users\kor_file\AppData\Roaming\Python\Python36\site-packages\werkzeug\routing.py", line 1799, in match
    raise NotFound()
werkzeug.exceptions.NotFound: 404 Not Found: The requested URL was not found on the server. If you entered the URL manually please check your spelling and try again.

During handling of the above exception, another exception occurred:

Traceback (most recent call last):
  File "C:\Users\kor_file\Anaconda3\envs\tensorflow_p36\lib\site-packages\flask\app.py", line 2446, in wsgi_app
    response = self.full_dispatch_request()
  File "C:\Users\kor_file\Anaconda3\envs\tensorflow_p36\lib\site-packages\flask\app.py", line 1951, in full_dispatch_request
    rv = self.handle_user_exception(e)
  File "C:\Users\kor_file\Anaconda3\envs\tensorflow_p36\lib\site-packages\flask_restful\__init__.py", line 269, in error_router
    return original_handler(e)
  File "C:\Users\kor_file\Anaconda3\envs\tensorflow_p36\lib\site-packages\flask_cors\extension.py", line 161, in wrapped_function
    return cors_after_request(app.make_response(f(*args, **kwargs)))
  File "C:\Users\kor_file\Anaconda3\envs\tensorflow_p36\lib\site-packages\flask\app.py", line 2130, in make_response
    " {rv.__class__.__name__}.".format(rv=rv)
TypeError: The view function did not return a valid response. The return type must be a string, dict, tuple, Response instance, or WSGI callable, but it was a int.

2020-02-21 09:54:24,715 Traceback (most recent call last):
  File "C:\Users\kor_file\Anaconda3\envs\tensorflow_p36\lib\site-packages\flask\app.py", line 1949, in full_dispatch_request
    rv = self.dispatch_request()
  File "C:\Users\kor_file\Anaconda3\envs\tensorflow_p36\lib\site-packages\flask\app.py", line 1925, in dispatch_request
    self.raise_routing_exception(req)
  File "C:\Users\kor_file\Anaconda3\envs\tensorflow_p36\lib\site-packages\flask\app.py", line 1907, in raise_routing_exception
    raise request.routing_exception
  File "C:\Users\kor_file\Anaconda3\envs\tensorflow_p36\lib\site-packages\flask\ctx.py", line 350, in match_request
    result = self.url_adapter.match(return_rule=True)
  File "C:\Users\kor_file\AppData\Roaming\Python\Python36\site-packages\werkzeug\routing.py", line 1799, in match
    raise NotFound()
werkzeug.exceptions.NotFound: 404 Not Found: The requested URL was not found on the server. If you entered the URL manually please check your spelling and try again.

2020-02-21 09:54:24,720 Traceback (most recent call last):
  File "C:\Users\kor_file\Anaconda3\envs\tensorflow_p36\lib\site-packages\flask\app.py", line 1949, in full_dispatch_request
    rv = self.dispatch_request()
  File "C:\Users\kor_file\Anaconda3\envs\tensorflow_p36\lib\site-packages\flask\app.py", line 1925, in dispatch_request
    self.raise_routing_exception(req)
  File "C:\Users\kor_file\Anaconda3\envs\tensorflow_p36\lib\site-packages\flask\app.py", line 1907, in raise_routing_exception
    raise request.routing_exception
  File "C:\Users\kor_file\Anaconda3\envs\tensorflow_p36\lib\site-packages\flask\ctx.py", line 350, in match_request
    result = self.url_adapter.match(return_rule=True)
  File "C:\Users\kor_file\AppData\Roaming\Python\Python36\site-packages\werkzeug\routing.py", line 1799, in match
    raise NotFound()
werkzeug.exceptions.NotFound: 404 Not Found: The requested URL was not found on the server. If you entered the URL manually please check your spelling and try again.

During handling of the above exception, another exception occurred:

Traceback (most recent call last):
  File "C:\Users\kor_file\Anaconda3\envs\tensorflow_p36\lib\site-packages\flask\app.py", line 2446, in wsgi_app
    response = self.full_dispatch_request()
  File "C:\Users\kor_file\Anaconda3\envs\tensorflow_p36\lib\site-packages\flask\app.py", line 1951, in full_dispatch_request
    rv = self.handle_user_exception(e)
  File "C:\Users\kor_file\Anaconda3\envs\tensorflow_p36\lib\site-packages\flask_restful\__init__.py", line 269, in error_router
    return original_handler(e)
  File "C:\Users\kor_file\Anaconda3\envs\tensorflow_p36\lib\site-packages\flask_cors\extension.py", line 161, in wrapped_function
    return cors_after_request(app.make_response(f(*args, **kwargs)))
  File "C:\Users\kor_file\Anaconda3\envs\tensorflow_p36\lib\site-packages\flask\app.py", line 2130, in make_response
    " {rv.__class__.__name__}.".format(rv=rv)
TypeError: The view function did not return a valid response. The return type must be a string, dict, tuple, Response instance, or WSGI callable, but it was a int.

